Workbook

Sheet Автоматизированный расчет
A1: Script name | B1: transaction rq | C1: count | D1: VU | E1: pacing | F1: одним пользователем в минуту | G1: Длительность ступени | H1: Итого | I1: transaction rq | J1: Сумма по полю Итого | M1: Операция (бизнес процесс) | N1: Duration | O1: Think_time | P1: Duration + Think_time | Q1: Pacing | R1: VU | S1: % Распределения пользователей | T1: Jmeter, throughput per minute | U1: Длительность ступени в минутах | V1: Интенсивность операций | W1: Всего пользователей на ступени | Z1: VU
A2: Покупка билета | B2: Главная Welcome страница | C2: 1 | D2: =VLOOKUP(A2,$M$1:$X$8,6,FALSE()) -> 2 | E2: =VLOOKUP(A2,$M$1:$X$8,5,FALSE()) -> 42 | F2: =60/E2*C2 -> 1.4285714 | G2: =VLOOKUP(A2,$M$1:$X$8,9,FALSE()) -> 20 | H2: =D2*F2*G2 -> 57.142857 | I2: Вход в систему | J2: 148.79121 | M2: Покупка билета | N2: 1 | O2: =3*7 -> 21 | P2: =N2+O2 -> 22 | Q2: 42 | R2: 2 | S2: =R2/W$2 -> 0.2 | T2: =60/(Q2) -> 1.4285714 | U2: 20 | V2: =ROUND(R2*T2*U2,0) -> 57 | W2: =SUM(R2:R7) -> 10 | Z2: 2
A3: Покупка билета | B3: Вход в систему | C3: 1 | D3: =VLOOKUP(A3,$M$1:$X$8,6,FALSE()) -> 2 | E3: =VLOOKUP(A3,$M$1:$X$8,5,FALSE()) -> 42 | F3: =60/E3*C3 -> 1.4285714 | G3: =VLOOKUP(A3,$M$1:$X$8,9,FALSE()) -> 20 | H3: =D3*F3*G3 -> 57.142857 | I3: Выбор рейса из найденных | J3: 94.642857 | M3: Удаление бронирования | N3: 5 | O3: =3*5 -> 15 | P3: =N3+O3 -> 20 | Q3: 52 | R3: 1 | S3: =R3/W$2 -> 0.1 | T3: =60/(Q3) -> 1.1538462 | U3: 20 | V3: =ROUND(R3*T3*U3,0) -> 23 | Z3: 1
A4: Покупка билета | B4: Переход на страницу поиска билетов | C4: 1 | D4: =VLOOKUP(A5,$M$1:$X$8,6,FALSE()) -> 2 | E4: =VLOOKUP(A5,$M$1:$X$8,5,FALSE()) -> 42 | F4: =60/E4*C4 -> 1.4285714 | G4: =VLOOKUP(A4,$M$1:$X$8,9,FALSE()) -> 20 | H4: =D4*F4*G4 -> 57.142857 | I4: Выход из системы | J4: 111.29121 | M4: Регистрация новых пользователей | N4: 3 | O4: =3*4 -> 12 | P4: =N4+O4 -> 15 | Q4: 38 | R4: 1 | S4: =R4/W$2 -> 0.1 | T4: =60/(Q4) -> 1.5789474 | U4: 20 | V4: =ROUND(R4*T4*U4,0) -> 32 | Z4: 1
A5: Покупка билета | B5: Заполнение полей для поиска билета | C5: 1 | D5: =VLOOKUP(A6,$M$1:$X$8,6,FALSE()) -> 2 | E5: =VLOOKUP(A6,$M$1:$X$8,5,FALSE()) -> 42 | F5: =60/E5*C5 -> 1.4285714 | G5: =VLOOKUP(A5,$M$1:$X$8,9,FALSE()) -> 20 | H5: =D5*F5*G5 -> 57.142857 | I5: Заполнение полей для поиска билета | J5: 94.642857 | M5: Поиск билета без покупки | N5: 3 | O5: =3*6 -> 18 | P5: 30 | Q5: 64 | R5: 2 | S5: =R5/W$2 -> 0.2 | T5: =60/(Q5) -> 0.9375 | U5: 20 | V5: =ROUND(R5*T5*U5,0) -> 38 | Z5: 2
A6: Покупка билета | B6: Выбор рейса из найденных | C6: 1 | D6: =VLOOKUP(A6,$M$1:$X$8,6,FALSE()) -> 2 | E6: =VLOOKUP(A6,$M$1:$X$8,5,FALSE()) -> 42 | F6: =60/E6*C6 -> 1.4285714 | G6: =VLOOKUP(A6,$M$1:$X$8,9,FALSE()) -> 20 | H6: =D6*F6*G6 -> 57.142857 | I6: Оплата билета | J6: 57.142857 | M6: Ознакомление с путевым листом | N6: 3 | O6: =3*4 -> 12 | P6: =N6+O6 -> 15 | Q6: 84 | R6: 2 | S6: =R6/W$2 -> 0.2 | T6: =60/(Q6) -> 0.71428571 | U6: 20 | V6: =ROUND(R6*T6*U6,0) -> 29 | Z6: 2
A7: Покупка билета | B7: Оплата билета | C7: 1 | D7: =VLOOKUP(A7,$M$1:$X$8,6,FALSE()) -> 2 | E7: =VLOOKUP(A7,$M$1:$X$8,5,FALSE()) -> 42 | F7: =60/E7*C7 -> 1.4285714 | G7: =VLOOKUP(A7,$M$1:$X$8,9,FALSE()) -> 20 | H7: =D7*F7*G7 -> 57.142857 | I7: Отмена бронирования | J7: 23.076923 | M7: Логин | N7: 0.61 | O7: =3*4 -> 12 | P7: =N7+O7 -> 12.61 | Q7: 960 | R7: 2 | S7: =R7/W$2 -> 0.2 | T7: =60/(Q7) -> 0.0625 | U7: 20 | V7: =SUM(V2:V6) -> 179 | Z7: 2
A8: Покупка билета | B8: Выход из системы | C8: 1 | D8: =VLOOKUP(A8,$M$1:$X$8,6,FALSE()) -> 2 | E8: =VLOOKUP(A8,$M$1:$X$8,5,FALSE()) -> 42 | F8: =60/E8*C8 -> 1.4285714 | G8: =VLOOKUP(A8,$M$1:$X$8,9,FALSE()) -> 20 | H8: =D8*F8*G8 -> 57.142857 | I8: Просмотр квитанций | J8: 89.148352 | S8: =SUM(S2:S7) -> 1
A9: Удаление бронирования | B9: Главная Welcome страница | C9: 1 | D9: =VLOOKUP(A9,$M$1:$X$8,6,FALSE()) -> 1 | E9: =VLOOKUP(A9,$M$1:$X$8,5,FALSE()) -> 52 | F9: =60/E9*C9 -> 1.1538462 | G9: =VLOOKUP(A9,$M$1:$X$8,9,FALSE()) -> 20 | H9: =D9*F9*G9 -> 23.076923 | I9: Главная Welcome страница | J9: 180.37016
A10: Удаление бронирования | B10: Вход в систему | C10: 1 | D10: =VLOOKUP(A10,$M$1:$X$8,6,FALSE()) -> 1 | E10: =VLOOKUP(A10,$M$1:$X$8,5,FALSE()) -> 52 | F10: =60/E10*C10 -> 1.1538462 | G10: =VLOOKUP(A10,$M$1:$X$8,9,FALSE()) -> 20 | H10: =D10*F10*G10 -> 23.076923 | I10: Перход на страницу регистрации | J10: 31.578947
A11: Удаление бронирования | B11: Просмотр квитанций | C11: 1 | D11: =VLOOKUP(A11,$M$1:$X$8,6,FALSE()) -> 1 | E11: =VLOOKUP(A11,$M$1:$X$8,5,FALSE()) -> 52 | F11: =60/E11*C11 -> 1.1538462 | G11: =VLOOKUP(A11,$M$1:$X$8,9,FALSE()) -> 20 | H11: =D11*F11*G11 -> 23.076923 | I11: Заполнение полей регистарции | J11: 31.578947
A12: Удаление бронирования | B12: Отмена бронирования | C12: 1 | D12: =VLOOKUP(A12,$M$1:$X$8,6,FALSE()) -> 1 | E12: =VLOOKUP(A12,$M$1:$X$8,5,FALSE()) -> 52 | F12: =60/E12*C12 -> 1.1538462 | G12: =VLOOKUP(A12,$M$1:$X$8,9,FALSE()) -> 20 | H12: =D12*F12*G12 -> 23.076923 | I12: Переход на следуюущий эран после регистарции | J12: 31.578947
A13: Удаление бронирования | B13: Выход из системы | C13: 1 | D13: =VLOOKUP(A13,$M$1:$X$8,6,FALSE()) -> 1 | E13: =VLOOKUP(A13,$M$1:$X$8,5,FALSE()) -> 52 | F13: =60/E13*C13 -> 1.1538462 | G13: =VLOOKUP(A13,$M$1:$X$8,9,FALSE()) -> 20 | H13: =D13*F13*G13 -> 23.076923 | I13: Переход на страницу поиска билетов | J13: 97.142857
A14: Регистрация новых пользователей | B14: Главная Welcome страница | C14: 1 | D14: =VLOOKUP(A14,$M$1:$X$8,6,FALSE()) -> 1 | E14: =VLOOKUP(A14,$M$1:$X$8,5,FALSE()) -> 38 | F14: =60/E14*C14 -> 1.5789474 | G14: =VLOOKUP(A14,$M$1:$X$8,9,FALSE()) -> 20 | H14: =D14*F14*G14 -> 31.578947 | I14: Итог Результат | J14: 990.98612
A15: Регистрация новых пользователей | B15: Перход на страницу регистрации | C15: 1 | D15: =VLOOKUP(A15,$M$1:$X$8,6,FALSE()) -> 1 | E15: =VLOOKUP(A15,$M$1:$X$8,5,FALSE()) -> 38 | F15: =60/E15*C15 -> 1.5789474 | G15: =VLOOKUP(A15,$M$1:$X$8,9,FALSE()) -> 20 | H15: =D15*F15*G15 -> 31.578947
A16: Регистрация новых пользователей | B16: Заполнение полей регистарции | C16: 1 | D16: =VLOOKUP(A16,$M$1:$X$8,6,FALSE()) -> 1 | E16: =VLOOKUP(A16,$M$1:$X$8,5,FALSE()) -> 38 | F16: =60/E16*C16 -> 1.5789474 | G16: =VLOOKUP(A16,$M$1:$X$8,9,FALSE()) -> 20 | H16: =D16*F16*G16 -> 31.578947
A17: Регистрация новых пользователей | B17: Переход на следуюущий эран после регистарции | C17: 1 | D17: =VLOOKUP(A17,$M$1:$X$8,6,FALSE()) -> 1 | E17: =VLOOKUP(A17,$M$1:$X$8,5,FALSE()) -> 38 | F17: =60/E17*C17 -> 1.5789474 | G17: =VLOOKUP(A17,$M$1:$X$8,9,FALSE()) -> 20 | H17: =D17*F17*G17 -> 31.578947
A18: Регистрация новых пользователей | B18: Выход из системы | C18: 0 | D18: =VLOOKUP(A18,$M$1:$X$8,6,FALSE()) -> 1 | E18: =VLOOKUP(A18,$M$1:$X$8,5,FALSE()) -> 38 | F18: =60/E18*C18 -> 0 | G18: =VLOOKUP(A18,$M$1:$X$8,9,FALSE()) -> 20 | H18: =D18*F18*G18 -> 0
A19: Логин | B19: Главная Welcome страница | C19: 1 | D19: =VLOOKUP(A19,$M$1:$X$8,6,FALSE()) -> 2 | E19: =VLOOKUP(A19,$M$1:$X$8,5,FALSE()) -> 960 | F19: =60/E19*C19 -> 0.0625 | G19: =VLOOKUP(A19,$M$1:$X$8,9,FALSE()) -> 20 | H19: =D19*F19*G19 -> 2.5
A20: Логин | B20: Вход в систему | C20: 1 | D20: =VLOOKUP(A20,$M$1:$X$8,6,FALSE()) -> 2 | E20: =VLOOKUP(A20,$M$1:$X$8,5,FALSE()) -> 960 | F20: =60/E20*C20 -> 0.0625 | G20: =VLOOKUP(A20,$M$1:$X$8,9,FALSE()) -> 20 | H20: =D20*F20*G20 -> 2.5
A21: Логин | B21: Переход на страницу поиска билетов | C21: 1 | D21: =VLOOKUP(A21,$M$1:$X$8,6,FALSE()) -> 2 | E21: =VLOOKUP(A21,$M$1:$X$8,5,FALSE()) -> 960 | F21: =60/E21*C21 -> 0.0625 | G21: =VLOOKUP(A21,$M$1:$X$8,9,FALSE()) -> 20 | H21: =D21*F21*G21 -> 2.5
A22: Логин | B22: Выход из системы | C22: 1 | D22: =VLOOKUP(A22,$M$1:$X$8,6,FALSE()) -> 2 | E22: =VLOOKUP(A22,$M$1:$X$8,5,FALSE()) -> 960 | F22: =60/E22*C22 -> 0.0625 | G22: =VLOOKUP(A22,$M$1:$X$8,9,FALSE()) -> 20 | H22: =D22*F22*G22 -> 2.5
A23: Поиск билета без покупки | B23: Главная Welcome страница | C23: 1 | D23: =VLOOKUP(A23,$M$1:$X$8,6,FALSE()) -> 2 | E23: =VLOOKUP(A23,$M$1:$X$8,5,FALSE()) -> 64 | F23: =60/E23*C23 -> 0.9375 | G23: =VLOOKUP(A23,$M$1:$X$8,9,FALSE()) -> 20 | H23: =D23*F23*G23 -> 37.5
A24: Поиск билета без покупки | B24: Вход в систему | C24: 1 | D24: =VLOOKUP(A24,$M$1:$X$8,6,FALSE()) -> 2 | E24: =VLOOKUP(A24,$M$1:$X$8,5,FALSE()) -> 64 | F24: =60/E24*C24 -> 0.9375 | G24: =VLOOKUP(A24,$M$1:$X$8,9,FALSE()) -> 20 | H24: =D24*F24*G24 -> 37.5
A25: Поиск билета без покупки | B25: Переход на страницу поиска билетов | C25: 1 | D25: =VLOOKUP(A25,$M$1:$X$8,6,FALSE()) -> 2 | E25: =VLOOKUP(A25,$M$1:$X$8,5,FALSE()) -> 64 | F25: =60/E25*C25 -> 0.9375 | G25: =VLOOKUP(A25,$M$1:$X$8,9,FALSE()) -> 20 | H25: =D25*F25*G25 -> 37.5
A26: Поиск билета без покупки | B26: Заполнение полей для поиска билета | C26: 1 | D26: =VLOOKUP(A26,$M$1:$X$8,6,FALSE()) -> 2 | E26: =VLOOKUP(A26,$M$1:$X$8,5,FALSE()) -> 64 | F26: =60/E26*C26 -> 0.9375 | G26: =VLOOKUP(A26,$M$1:$X$8,9,FALSE()) -> 20 | H26: =D26*F26*G26 -> 37.5
... A33: Ознакомление с путевым листом | B33: Выход из системы | C33: 1 | D33: =VLOOKUP(A33,$M$1:$X$8,6,FALSE()) -> 2 | E33: =VLOOKUP(A33,$M$1:$X$8,5,FALSE()) -> 84 | F33: =60/E33*C33 -> 0.71428571 | G33: =VLOOKUP(A33,$M$1:$X$8,9,FALSE()) -> 20 | H33: =D33*F33*G33 -> 28.571429
A36: Статистика с ПРОДа | C36: Профиль
A37: Название запроса | B37: Интенсивность по статистике запросов / час | C37: Расчетная интенсивность запросов / час | D37: % Соотвествия расчетанной интенсивности статистики | F37: ScriptName | G37: Расчетная интенсивность запросов / 20 мин | H37: Фактическая интенсивность в тесте | I37: % Отклонение от Профиля
A38: Главная Welcome страница | B38: 520 | C38: =GETPIVOTDATA("Итого",$I$1,"transaction rq",A38)*3 -> 541.11047 | D38: =1-B38/C38 -> 0.039013232 | F38: =VLOOKUP(A38,Соответствие!A:B,2,FALSE()) -> Welcome | G38: =C38/3 -> 180.37016 | H38: 180 | I38: =1-G38/H38 -> -0.0020564231
A39: Вход в систему | B39: 422 | C39: =GETPIVOTDATA("Итого",$I$1,"transaction rq",A39)*3 -> 446.37363 | D39: =1-B39/C39 -> 0.054603644 | F39: =VLOOKUP(A39,Соответствие!A:B,2,FALSE()) -> Login | G39: =C39/3 -> 148.79121 | H39: 147 | I39: =1-G39/H39 -> -0.012185094
A40: Переход на страницу поиска билетов | B40: 305 | C40: =GETPIVOTDATA("Итого",$I$1,"transaction rq",A40)*3 -> 291.42857 | D40: =1-B40/C40 -> -0.046568627 | F40: =VLOOKUP(A40,Соответствие!A:B,2,FALSE()) -> Flights | G40: =C40/3 -> 97.142857 | H40: 97 | I40: =1-G40/H40 -> -0.0014727541
A41: Заполнение полей для поиска билета | B41: 282 | C41: =GETPIVOTDATA("Итого",$I$1,"transaction rq",A41)*3 -> 283.92857 | D41: =1-B41/C41 -> 0.0067924528 | F41: =VLOOKUP(A41,Соответствие!A:B,2,FALSE()) -> Find_flight | G41: =C41/3 -> 94.642857 | H41: 95 | I41: =1-G41/H41 -> 0.0037593985
A42: Выбор рейса из найденных | B42: 270 | C42: =GETPIVOTDATA("Итого",$I$1,"transaction rq",A42)*3 -> 283.92857 | D42: =1-B42/C42 -> 0.049056604 | F42: =VLOOKUP(A42,Соответствие!A:B,2,FALSE()) -> Payment_details | G42: =C42/3 -> 94.642857 | H42: 95 | I42: =1-G42/H42 -> 0.0037593985
A43: Оплата билета | B43: 175 | C43: =GETPIVOTDATA("Итого",$I$1,"transaction rq",A43)*3 -> 171.42857 | D43: =1-B43/C43 -> -0.020833333 | F43: =VLOOKUP(A43,Соответствие!A:B,2,FALSE()) -> Invoice | G43: =C43/3 -> 57.142857 | H43: 58 | I43: =1-G43/H43 -> 0.014778325
A44: Просмотр квитанций | B44: 280 | C44: =GETPIVOTDATA("Итого",$I$1,"transaction rq",A44)*3 -> 267.44505 | D44: =1-B44/C44 -> -0.046944016 | F44: =VLOOKUP(A44,Соответствие!A:B,2,FALSE()) -> Itinerary | G44: =C44/3 -> 89.148352 | H44: 89 | I44: =1-G44/H44 -> -0.0016668725
A45: Отмена бронирования | B45: 73 | C45: =GETPIVOTDATA("Итого",$I$1,"transaction rq",A45)*3 -> 69.230769 | D45: =1-B45/C45 -> -0.054444444 | F45: =VLOOKUP(A45,Соответствие!A:B,2,FALSE()) -> Delete_one_itineraries | G45: =C45/3 -> 23.076923 | H45: 23 | I45: =1-G45/H45 -> -0.0033444816
A46: Выход из системы | B46: 326 | C46: =GETPIVOTDATA("Итого",$I$1,"transaction rq",A46)*3 -> 333.87363 | D46: =1-B46/C46 -> 0.023582654 | F46: =VLOOKUP(A46,Соответствие!A:B,2,FALSE()) -> Logout | G46: =C46/3 -> 111.29121 | H46: 110 | I46: =1-G46/H46 -> -0.011738262
A47: Перход на страницу регистрации | B47: 97 | C47: =GETPIVOTDATA("Итого",$I$1,"transaction rq",A47)*3 -> 94.736842 | D47: =1-B47/C47 -> -0.023888889 | F47: =VLOOKUP(A47,Соответствие!A:B,2,FALSE()) -> Signup | G47: =C47/3 -> 31.578947 | H47: 31 | I47: =1-G47/H47 -> -0.018675722
A48: Заполнение полей регистарции | B48: 97 | C48: =GETPIVOTDATA("Итого",$I$1,"transaction rq",A48)*3 -> 94.736842 | D48: =1-B48/C48 -> -0.023888889 | F48: =VLOOKUP(A48,Соответствие!A:B,2,FALSE()) -> Signup_done | G48: =C48/3 -> 31.578947 | H48: 31 | I48: =1-G48/H48 -> -0.018675722
...

Sheet Соответствие
A1: Имя в статистике | B1: Имя в скрипте
A2: ='Автоматизированный расчет'!A38 -> Главная Welcome страница | B2: Welcome
A3: ='Автоматизированный расчет'!A39 -> Вход в систему | B3: Login
A4: ='Автоматизированный расчет'!A40 -> Переход на страницу поиска билетов | B4: Flights
A5: ='Автоматизированный расчет'!A41 -> Заполнение полей для поиска билета | B5: Find_flight
A6: ='Автоматизированный расчет'!A42 -> Выбор рейса из найденных | B6: Payment_details
A7: ='Автоматизированный расчет'!A43 -> Оплата билета | B7: Invoice
A8: ='Автоматизированный расчет'!A44 -> Просмотр квитанций | B8: Itinerary
A9: ='Автоматизированный расчет'!A45 -> Отмена бронирования | B9: Delete_one_itineraries
A10: ='Автоматизированный расчет'!A46 -> Выход из системы | B10: Logout
A11: ='Автоматизированный расчет'!A47 -> Перход на страницу регистрации | B11: Signup
A12: ='Автоматизированный расчет'!A48 -> Заполнение полей регистарции | B12: Signup_done
A13: ='Автоматизированный расчет'!A49 -> Переход на следуюущий эран после регистарции | B13: Login_after_registration

Sheet SummaryReport
A1: Transaction Name | B1: SLA Status | C1: Minimum | D1: Average | E1: Maximum | F1: Std. Deviation | G1: 90 Percent | H1: Pass | I1: Fail | J1: Stop
A2: Action_Transaction | B2: No Data | C2: 0.454 | D2: 0.863 | E2: 1.232 | F2: 0.184 | G2: 1.097 | H2: 178 | I2: 0 | J2: 0
A3: cancelChecked | B3: No Data | C3: 0 | D3: 0.129 | E3: 0.214 | F3: 0.076 | G3: 0.192 | H3: 24 | I3: 0 | J3: 0
A4: clickFlights | B4: No Data | C4: 0.16 | D4: 0.208 | E4: 0.423 | F4: 0.041 | G4: 0.243 | H4: 97 | I4: 0 | J4: 0
A5: clickItinerary | B5: No Data | C5: 0.182 | D5: 0.211 | E5: 0.347 | F5: 0.026 | G5: 0.228 | H5: 96 | I5: 0 | J5: 0
A6: confirmSignUp | B6: No Data | C6: 0.148 | D6: 0.178 | E6: 0.231 | F6: 0.019 | G6: 0.205 | H6: 32 | I6: 0 | J6: 0
A7: findFlight | B7: No Data | C7: 0.079 | D7: 0.092 | E7: 0.21 | F7: 0.014 | G7: 0.1 | H7: 98 | I7: 0 | J7: 0
A8: login | B8: No Data | C8: 0.152 | D8: 0.182 | E8: 0.34 | F8: 0.023 | G8: 0.208 | H8: 146 | I8: 0 | J8: 0
A9: openHomePage | B9: No Data | C9: 0.145 | D9: 0.17 | E9: 0.346 | F9: 0.022 | G9: 0.186 | H9: 178 | I9: 0 | J9: 0
A10: paymentDetails | B10: No Data | C10: 0.088 | D10: 0.1 | E10: 0.132 | F10: 0.009 | G10: 0.109 | H10: 60 | I10: 0 | J10: 0
A11: profileDataEntry | B11: No Data | C11: 0.072 | D11: 0.086 | E11: 0.143 | F11: 0.014 | G11: 0.095 | H11: 32 | I11: 0 | J11: 0
A12: selectTicket | B12: No Data | C12: 0.081 | D12: 0.097 | E12: 0.172 | F12: 0.014 | G12: 0.108 | H12: 90 | I12: 0 | J12: 0
A13: signOff | B13: No Data | C13: 0.136 | D13: 0.158 | E13: 0.394 | F13: 0.027 | G13: 0.175 | H13: 110 | I13: 0 | J13: 0
... A21: UC07_login | B21: No Data | C21: 0.453 | D21: 0.497 | E21: 0.564 | F21: 0.027 | G21: 0.508 | H21: 12 | I21: 0 | J21: 0

Sheet Результаты всех тестов
E3: Профиль для 10 пользователей
E5: Наименование операции | F5: Наименование транзакции | G5: По профилю | H5: По факту | I5: % отклонения | K5: 20 min | L5: requests | M5: Requests total
E6: Главная Welcome страница | F6: Welcome | G6: 541 | H6: 540 | I6: =1-G6/H6 -> -0.0018518519 | K6: 180 | L6: 3 | M6: =H6*L6 -> 1620
E7: Вход в систему | F7: Login | G7: 446 | H7: 441 | I7: =1-G7/H7 -> -0.011337868 | K7: 147 | L7: 3 | M7: =H7*L7 -> 1323
E8: Переход на страницу поиска билетов | F8: Flights | G8: 291 | H8: 291 | I8: =1-G8/H8 -> 0 | K8: 97 | L8: 3 | M8: =H8*L8 -> 873
E9: Заполнение полей для поиска билета | F9: Find_flight | G9: 284 | H9: 285 | I9: =1-G9/H9 -> 0.0035087719 | K9: 95 | L9: 1 | M9: =H9*L9 -> 285
E10: Выбор рейса из найденных | F10: Payment_details | G10: 284 | H10: 285 | I10: =1-G10/H10 -> 0.0035087719 | K10: 95 | L10: 1 | M10: =H10*L10 -> 285
E11: Оплата билета | F11: Invoice | G11: 171 | H11: 174 | I11: =1-G11/H11 -> 0.017241379 | K11: 58 | L11: 1 | M11: =H11*L11 -> 174
E12: Просмотр квитанций | F12: Itinerary | G12: 267 | H12: 267 | I12: =1-G12/H12 -> 0 | K12: 89 | L12: 3 | M12: =H12*L12 -> 801
E13: Отмена бронирования | F13: Delete_one_itineraries | G13: 69 | H13: 69 | I13: =1-G13/H13 -> 0 | K13: 23 | L13: 1 | M13: =H13*L13 -> 69
E14: Выход из системы | F14: Logout | G14: 334 | H14: 330 | I14: =1-G14/H14 -> -0.012121212 | K14: 110 | L14: 2 | M14: =H14*L14 -> 660
E15: Переход на страницу регистрации | F15: Signup | G15: 95 | H15: 93 | I15: =1-G15/H15 -> -0.021505376 | K15: 31 | L15: 1 | M15: =H15*L15 -> 93
E16: Заполнение полей регистрации | F16: Signup_done | G16: 95 | H16: 93 | I16: =1-G16/H16 -> -0.021505376 | K16: 31 | L16: 1 | M16: =H16*L16 -> 93
E17: Переход на следующий экран после регистрации | F17: Login_after_registration | G17: 95 | H17: 93 | I17: =1-G17/H17 -> -0.021505376 | K17: 31 | L17: 3 | M17: =H17*L17 -> 279
E18: Итого | G18: =SUM(G6:G17) -> 2972 | H18: =SUM(H6:H17) -> 2961 | M18: =SUM(M6:M17) -> 6555
E23: Поиск максимума 2 ступень 20 пользователей
E25: Наименование операции | F25: Наименование транзакции | G25: По профилю | H25: По факту | I25: % отклонения | K25: 20 min | L25: requests | M25: Requests total
E26: Главная Welcome страница | F26: Welcome | G26: 1082 | H26: =K26*3 -> 1077 | I26: =1-G26/H26 -> -0.0046425255 | K26: 359 | L26: 3 | M26: =H26*L26 -> 3231
E27: Вход в систему | F27: Login | G27: 893 | H27: =K27*3 -> 891 | I27: =1-G27/H27 -> -0.0022446689 | K27: 297 | L27: 3 | M27: =H27*L27 -> 2673
E28: Переход на страницу поиска билетов | F28: Flights | G28: 583 | H28: =K28*3 -> 576 | I28: =1-G28/H28 -> -0.012152778 | K28: 192 | L28: 3 | M28: =H28*L28 -> 1728
E29: Заполнение полей для поиска билета | F29: Find_flight | G29: 568 | H29: =K29*3 -> 570 | I29: =1-G29/H29 -> 0.0035087719 | K29: 190 | L29: 1 | M29: =H29*L29 -> 570
E30: Выбор рейса из найденных | F30: Payment_details | G30: 568 | H30: =K30*3 -> 573 | I30: =1-G30/H30 -> 0.0087260035 | K30: 191 | L30: 1 | M30: =H30*L30 -> 573
E31: Оплата билета | F31: Invoice | G31: 343 | H31: =K31*3 -> 345 | I31: =1-G31/H31 -> 0.0057971014 | K31: 115 | L31: 1 | M31: =H31*L31 -> 345
E32: Просмотр квитанций | F32: Itinerary | G32: 535 | H32: =K32*3 -> 534 | I32: =1-G32/H32 -> -0.0018726592 | K32: 178 | L32: 3 | M32: =H32*L32 -> 1602
E33: Отмена бронирования | F33: Delete_one_itineraries | G33: 138 | H33: =K33*3 -> 135 | I33: =1-G33/H33 -> -0.022222222 | K33: 45 | L33: 1 | M33: =H33*L33 -> 135
E34: Выход из системы | F34: Logout | G34: 668 | H34: =K34*3 -> 669 | I34: =1-G34/H34 -> 0.0014947683 | K34: 223 | L34: 2 | M34: =H34*L34 -> 1338
E35: Переход на страницу регистрации | F35: Signup | G35: 189 | H35: =K35*3 -> 189 | I35: =1-G35/H35 -> 0 | K35: 63 | L35: 1 | M35: =H35*L35 -> 189
E36: Заполнение полей регистрации | F36: Signup_done | G36: 189 | H36: =K36*3 -> 189 | I36: =1-G36/H36 -> 0 | K36: 63 | L36: 1 | M36: =H36*L36 -> 189
E37: Переход на следующий экран после регистрации | F37: Login_after_registration | G37: 189 | H37: =K37*3 -> 189 | I37: =1-G37/H37 -> 0 | K37: 63 | L37: 3 | M37: =H37*L37 -> 567
E38: Итого | G38: =SUM(G26:G37) -> 5945 | H38: =SUM(H26:H37) -> 5937 | M38: =SUM(M26:M37) -> 13140
E41: Подтверждение максимума 2 ступень 20 пользователей
E43: Наименование операции | F43: Наименование транзакции | G43: По профилю | H43: По факту | I43: % отклонения | K43: 20 min | L43: requests | M43: Requests total
E44: Главная Welcome страница | F44: Welcome | G44: 1082 | H44: 1077 | I44: =1-G44/H44 -> -0.0046425255 | L44: 3 | M44: =H44*L44 -> 3231
E45: Вход в систему | F45: Login | G45: 893 | H45: 889 | I45: =1-G45/H45 -> -0.0044994376 | L45: 3 | M45: =H45*L45 -> 2667
E46: Переход на страницу поиска билетов | F46: Flights | G46: 583 | H46: 580 | I46: =1-G46/H46 -> -0.0051724138 | L46: 3 | M46: =H46*L46 -> 1740
E47: Заполнение полей для поиска билета | F47: Find_flight | G47: 568 | H47: 568 | I47: =1-G47/H47 -> 0 | L47: 1 | M47: =H47*L47 -> 568
E48: Выбор рейса из найденных | F48: Payment_details | G48: 568 | H48: 569 | I48: =1-G48/H48 -> 0.0017574692 | L48: 1 | M48: =H48*L48 -> 569
E49: Оплата билета | F49: Invoice | G49: 343 | H49: 342 | I49: =1-G49/H49 -> -0.0029239766 | L49: 1 | M49: =H49*L49 -> 342
E50: Просмотр квитанций | F50: Itinerary | G50: 535 | H50: 533 | I50: =1-G50/H50 -> -0.0037523452 | L50: 3 | M50: =H50*L50 -> 1599
E51: Отмена бронирования | F51: Delete_one_itineraries | G51: 138 | H51: 138 | I51: =1-G51/H51 -> 0 | L51: 1 | M51: =H51*L51 -> 138
...
